Workbook

Sheet 使い方
A1: ガチャ設計テンプレート v3.0（末広がり事案の再発防止・完全版）
A3: ■ 30秒でわかる使い方
A4: 1.「設計入力」シートの黄色いセル（青い文字）を埋める。白いセルは全部自動計算なので触らない。
A5: 2.「自動判定」シートを開く。黄色い入力は5箇所（外部付与率・安全上限・実測変換率・許容損失ライン・想定進捗率）。既定値のままでも動く。
A6: 3. いちばん下の ■総合判定 が「OK 公開可」になるまで設計を直す。赤いNG行には直し方、オレンジの注意行には判断材料が書いてある。
A7: 4.「公開前チェック」でバナーの数字と突合し、手動チェックリストを全部埋める。■公開前総合 がOKになったら公開。
A8: 5. 計算の意味がわからなくなったら「計算式リスト」を見る。全計算式と電卓用の逆算式が例つきで載っている。
A10: ■ 色のルール
A11: このセルの色（薄い黄色＋青い文字）＝ あなたが入力する場所
A12: このセル（白＋黒い文字）＝ 自動計算。編集しない・消さない
A13: 判定の色： 緑＝OK ／ 赤＝NG（公開不可） ／ オレンジ＝注意（公開は可・内容確認のうえ判断） ／ グレー＝未入力・未使用
A14: ■ シート構成
... A38: 新しいガチャを設計するときは、設計入力の黄色いセルの中身だけをDeleteで消してから使う（白いセルの式は消さない）。

Sheet 設計入力
A1: ① 設計入力 — 入力するのはこのシートの黄色いセルだけ
A2: 黄色＋青字＝入力 ／ 白＝自動計算（触らない）。いま入っているのはデモ（NG例）。実際に使うときは黄色セルの中身を消してから。
A3: 基本情報
A4: ガチャタイトル | D4: 1/319の天門を開け! アビスアイver | E4: 管理用の名前。仮/テスト等の文字は本番前に消す
A5: 単価（pt/口） | D5: 53 | E5: 1口の価格。1pt＝1円
A6: 総口数 | D6: 15950 | E6: このガチャの口数。賞品テーブルの口数合計と一致が必須
A7: 1人あたり購入上限（口/日） | D7: なし | E7: 未設定だと自動判定でNG。買い占め・ループ対策
A8: 1人あたり購入上限（口/累計） | D8: なし | E8: 同上。1人が期間中に買える上限
A9: pt実質原価率 | E9: 1ptを商品で消化するときの実コスト。既定0.72＝1ptあたり約0.72円。変える場合は税理士と相談
A10: 総売上（pt＝円） | D10: =IF(OR(D5="",D6=""),"",D5*D6) -> 845350 | E10: 自動計算：単価 × 総口数。完売時の売上規模
A11: 賞品テーブル（黄色セルを入力。J〜M列は自動計算。N列の確保在庫は任意）
A12: 賞ランク | B12: 賞品名 | C12: 型番 | D12: 口数 | E12: 実価値/枚 (円) | F12: 送料/件 (円) | G12: 受取方法 | H12: 上乗せ倍率 | I12: 表示PT 直接指定(任意) | J12: 表示PT/枚 (自動) | K12: 表示PT小計 (自動) | L12: 実価値小計 (自動) | M12: 出現率 (自動) | N12: 確保在庫 (任意) | O12: メモ
A13: 1等 | B13: アビスアイ | C13: - | D13: 50 | E13: 11200 | F13: 500 | G13: 選択制 | H13: 1.43 | J13: =IF($D13="","",IF($I13<>"",$I13,IF($H13="","",ROUND($E13*$H13,0)))) -> 16016 | K13: =IF($D13="","",$D13*$J13) -> 800800 | L13: =IF($D13="","",$D13*$E13) -> 560000 | M13: =IF($D13="","",$D13/$D$6) -> 0.0031347962
A14: その他 | B14: 2pt交換専用 | C14: - | D14: 5900 | E14: 1 | F14: 0 | G14: pt限定 | H14: 2 | J14: =IF($D14="","",IF($I14<>"",$I14,IF($H14="","",ROUND($E14*$H14,0)))) -> 2 | K14: =IF($D14="","",$D14*$J14) -> 11800 | L14: =IF($D14="","",$D14*$E14) -> 5900 | M14: =IF($D14="","",$D14/$D$6) -> 0.36990596
A15: その他 | B15: 1pt交換専用 | D15: 10000 | E15: 1 | F15: 0 | G15: pt限定 | H15: 1 | J15: =IF($D15="","",IF($I15<>"",$I15,IF($H15="","",ROUND($E15*$H15,0)))) -> 1 | K15: =IF($D15="","",$D15*$J15) -> 10000 | L15: =IF($D15="","",$D15*$E15) -> 10000 | M15: =IF($D15="","",$D15/$D$6) -> 0.62695925
J16: =IF($D16="","",IF($I16<>"",$I16,IF($H16="","",ROUND($E16*$H16,0)))) | K16: =IF($D16="","",$D16*$J16) | L16: =IF($D16="","",$D16*$E16) | M16: =IF($D16="","",$D16/$D$6)
J17: =IF($D17="","",IF($I17<>"",$I17,IF($H17="","",ROUND($E17*$H17,0)))) | K17: =IF($D17="","",$D17*$J17) | L17: =IF($D17="","",$D17*$E17) | M17: =IF($D17="","",$D17/$D$6)
J18: =IF($D18="","",IF($I18<>"",$I18,IF($H18="","",ROUND($E18*$H18,0)))) | K18: =IF($D18="","",$D18*$J18) | L18: =IF($D18="","",$D18*$E18) | M18: =IF($D18="","",$D18/$D$6)
J19: =IF($D19="","",IF($I19<>"",$I19,IF($H19="","",ROUND($E19*$H19,0)))) | K19: =IF($D19="","",$D19*$J19) | L19: =IF($D19="","",$D19*$E19) | M19: =IF($D19="","",$D19/$D$6)
J20: =IF($D20="","",IF($I20<>"",$I20,IF($H20="","",ROUND($E20*$H20,0)))) | K20: =IF($D20="","",$D20*$J20) | L20: =IF($D20="","",$D20*$E20) | M20: =IF($D20="","",$D20/$D$6)
J21: =IF($D21="","",IF($I21<>"",$I21,IF($H21="","",ROUND($E21*$H21,0)))) | K21: =IF($D21="","",$D21*$J21) | L21: =IF($D21="","",$D21*$E21) | M21: =IF($D21="","",$D21/$D$6)
J22: =IF($D22="","",IF($I22<>"",$I22,IF($H22="","",ROUND($E22*$H22,0)))) | K22: =IF($D22="","",$D22*$J22) | L22: =IF($D22="","",$D22*$E22) | M22: =IF($D22="","",$D22/$D$6)
J23: =IF($D23="","",IF($I23<>"",$I23,IF($H23="","",ROUND($E23*$H23,0)))) | K23: =IF($D23="","",$D23*$J23) | L23: =IF($D23="","",$D23*$E23) | M23: =IF($D23="","",$D23/$D$6)
J24: =IF($D24="","",IF($I24<>"",$I24,IF($H24="","",ROUND($E24*$H24,0)))) | K24: =IF($D24="","",$D24*$J24) | L24: =IF($D24="","",$D24*$E24) | M24: =IF($D24="","",$D24/$D$6)
J25: =IF($D25="","",IF($I25<>"",$I25,IF($H25="","",ROUND($E25*$H25,0)))) | K25: =IF($D25="","",$D25*$J25) | L25: =IF($D25="","",$D25*$E25) | M25: =IF($D25="","",$D25/$D$6)
J26: =IFERROR(I26*G26,"") -> 0
J27: =IF($D27="","",IF($I27<>"",$I27,IF($H27="","",ROUND($E27*$H27,0)))) | K27: =IF($D27="","",$D27*$J27) | L27: =IF($D27="","",$D27*$E27) | M27: =IF($D27="","",$D27/$D$6)
J28: =IF($D28="","",IF($I28<>"",$I28,IF($H28="","",ROUND($E28*$H28,0)))) | K28: =IF($D28="","",$D28*$J28) | L28: =IF($D28="","",$D28*$E28) | M28: =IF($D28="","",$D28/$D$6)
J29: =IF($D29="","",IF($I29<>"",$I29,IF($H29="","",ROUND($E29*$H29,0)))) | K29: =IF($D29="","",$D29*$J29) | L29: =IF($D29="","",$D29*$E29) | M29: =IF($D29="","",$D29/$D$6)
J30: =IF($D30="","",IF($I30<>"",$I30,IF($H30="","",ROUND($E30*$H30,0)))) | K30: =IF($D30="","",$D30*$J30) | L30: =IF($D30="","",$D30*$E30) | M30: =IF($D30="","",$D30/$D$6)
J31: =IF($D31="","",IF($I31<>"",$I31,IF($H31="","",ROUND($E31*$H31,0)))) | K31: =IF($D31="","",$D31*$J31) | L31: =IF($D31="","",$D31*$E31) | M31: =IF($D31="","",$D31/$D$6)
J32: =IF($D32="","",IF($I32<>"",$I32,IF($H32="","",ROUND($E32*$H32,0)))) | K32: =IF($D32="","",$D32*$J32) | L32: =IF($D32="","",$D32*$E32) | M32: =IF($D32="","",$D32/$D$6)
J33: =IF($D33="","",IF($I33<>"",$I33,IF($H33="","",ROUND($E33*$H33,0)))) | K33: =IF($D33="","",$D33*$J33) | L33: =IF($D33="","",$D33*$E33) | M33: =IF($D33="","",$D33/$D$6)
A34: 合計 | D34: =SUM(D13:D33) -> 15950 | K34: =SUM(K13:K33) -> 822600 | L34: =SUM(L13:L33) -> 575900 | M34: =IF($D$6="","",SUM(M13:M33)) -> 1 | N34: =SUM(N13:N33) -> 0
A36: ※ 表示PT/枚の決まり方：「表示PT直接指定」があればその値。空欄なら 実価値 × 上乗せ倍率（四捨五入）。※ 確保在庫を入力した行は「在庫≧口数」を自動判定でチェック（オーバーセル防止）。空欄の行はチェック対象外。

Sheet 自動判定
A1: ② 自動判定 — ■総合判定が「OK 公開可」になるまで公開不可
A2: 入力は黄色の5箇所（外部付与見込み・安全上限・実測変換率・許容損失ライン・想定進捗率）だけ。既定値のままでも動く。あとは全部自動。
A3: 項目 | B3: 値 | C3: 判定 | D3: 説明・NG/注意のときの直し方
A4: 基本数値・EV（実効EVがこの表の心臓部）
A5: 総売上（pt＝円） | B5: ='設計入力'!D10 -> 845350 | D5: 単価 × 総口数。完売時にお客様から入るptの総額
A6: 賞品口数の合計 | B6: ='設計入力'!D34 -> 15950 | C6: =IF('設計入力'!D6="","未入力（総口数を入力）",IF(B6='設計入力'!D6,"OK 総口数と一致","NG 差 "&TEXT('設計入力'!D6-B6,"#,##0")&" 口")) -> OK 総口数と一致 | D6: 483口事案の再発防止。賞品の口数を足すと総口数ぴったりになること
A7: 表示PT合計（全賞品） | B7: ='設計入力'!K34 -> 822600 | D7: お客様に付与しうるptの総額（額面）
A8: 総還元率（表示ベース） | B8: =IF(OR(B5="",B7=0),"",B7/B5) -> 0.97308807 | D8: 表示PT合計 ÷ 総売上。バナーに書く「◯%」
A9: 発送限定の表示PT | B9: =SUMIF('設計入力'!G13:G33,"発送限定",'設計入力'!K13:K33) -> 0 | D9: ptに変換できない賞の分。100%超の見せ場はここで作る
A10: pt建て表示PT（発送限定を除く） | B10: =B7-B9 -> 822600 | D10: pt残高になり得る分＝選択制＋pt限定の表示PT
A11: pt建てEV（このガチャ単体） | B11: =IF(OR(B5="",B7=0),"",B10/B5) -> 0.97308807 | D11: pt建て表示PT ÷ 総売上。ガチャ単体でptとして戻り得る割合
A12: 外部付与見込み（売上比） | B12: 0.02 | D12: クーポン・紹介pt・レベル報酬など、ガチャ外で配るptの売上比。迷ったら2%のまま。キャンペーン強化月は上げる
A13: ★ 実効pt建てEV（単体＋外部付与） | B13: =IF(OR(B11="",B12=""),"",B11+B12) -> 0.99308807 | C13: =IF(B13="","未入力",IF(B13>=1,"NG 公開不可：実効EV≧100%（ポイント再投入で増殖）",IF(B13>=B14,"注意 実効EVが安全上限以上（マージン不足）","OK 安全上限未満"))) -> 注意 実効EVが安全上限以上（マージン不足） | D13: 末広がり事案の主因。NGなら①発送限定に賞を移す ②4等などpt側の表示PTを削る ③単価/口数を見直す
A14: 実効EVの安全上限（社内ルール） | B14: 0.95 | D14: 実効EVがこの値以上で注意。既定95%＝実装誤差・外部施策のブレを吸収するマージン
A15: 発送限定分の還元率（見せ場分） | B15: =IF(OR(B5="",B7=0),"",B9/B5) -> 0 | D15: 総還元率のうち、発送でしか受け取れない分
A17: データ完全性（入力漏れ・在庫）
A18: 基本情報の必須欄 | C18: =IF(OR('設計入力'!D5="",'設計入力'!D6="",'設計入力'!D9=""),"未入力（単価・総口数・原価率）",IF(AND('設計入力'!D9>0,'設計入力'!D9<=1),"OK 入力済み","NG 原価率は0〜1の範囲で入力（例：0.72）")) -> 未入力（単価・総口数・原価率） | D18: 単価・総口数・pt実質原価率の3つ。原価率は割合（0.72）で入れる。72と入れると判定が壊れるのでNGにする
A19: 受取方法が未設定の行 | B19: =SUMPRODUCT(('設計入力'!D13:D33<>"")*('設計入力'!G13:G33="")) -> 0 | C19: =IF(B19=0,"OK なし","NG "&B19&" 行：受取方法（発送限定/選択制/pt限定）を選択") -> OK なし | D19: 空欄のままだとEV・損益の集計から漏れて判定が甘くなるためNG
A20: 表示PT/枚が確定しない行 | B20: =SUMPRODUCT(('設計入力'!D13:D33<>"")*('設計入力'!J13:J33="")) -> 0 | C20: =IF(B20=0,"OK なし","NG "&B20&" 行：上乗せ倍率か表示PT直接指定のどちらかを入力") -> OK なし | D20: 倍率も直接指定も空だと表示PTが計算できず、EVが過小評価される（危険側）ためNG
A21: 実価値/送料が未入力の行（pt限定以外） | B21: =SUMPRODUCT(('設計入力'!D13:D33<>"")*('設計入力'!G13:G33<>"pt限定")*((('設計入力'!E13:E33="")+('設計入力'!F13:F33=""))>0)) -> 0 | C21: =IF(B21=0,"OK なし","NG "&B21&" 行：実価値と送料を入力（0円なら0と入れる）") -> OK なし | D21: 空欄だと損益シナリオが甘く出る。0円なら明示的に0を入力
A22: 確保在庫が口数に足りない行 | B22: =SUMPRODUCT(('設計入力'!D13:D33<>"")*('設計入力'!N13:N33<>"")*('設計入力'!N13:N33<'設計入力'!D13:D33)) -> 0 | C22: =IF(SUMPRODUCT(('設計入力'!D13:D33<>"")*('設計入力'!N13:N33<>""))=0,"—（在庫列 未使用）",IF(B22=0,"OK 不足なし（"&SUMPRODUCT(('設計入力'!D13:D33<>"")*('設計入力'!N13:N33<>""))&"行を確認）","NG "&B22&" 行：在庫＜口数（オーバーセル）")) -> —（在庫列 未使用） | D22: 設計入力N列に確保在庫を入れた行だけチェック。空欄の行は対象外
A24: 損益シナリオ（完売時）
A25: 発送可能賞の実価値＋送料合計 | B25: =SUMIF('設計入力'!G13:G33,"<>pt限定",'設計入力'!L13:L33)+SUMPRODUCT(('設計入力'!G13:G33<>"pt限定")*('設計入力'!D13:D33)*('設計入力'!F13:F33)) -> 585000 | D25: 発送限定＋選択制の（実価値小計＋口数×送料）
A26: うち発送限定のみ | B26: =SUMIF('設計入力'!G13:G33,"発送限定",'設計入力'!L13:L33)+SUMPRODUCT(('設計入力'!G13:G33="発送限定")*('設計入力'!D13:D33)*('設計入力'!F13:F33)) -> 0 | D26: 必ず発送になる分の実費
A27: pt限定の表示PT（最低保証等） | B27: =SUMIF('設計入力'!G13:G33,"pt限定",'設計入力'!K13:K33) -> 21800 | D27: 必ずptで付与される分
A28: 選択制の表示PT | B28: =SUMIF('設計入力'!G13:G33,"選択制",'設計入力'!K13:K33) -> 800800 | D28: お客様が発送かpt変換かを選べる分の額面
A29: 選択制の実価値＋送料 | B29: =B25-B26 -> 585000 | D29: 選択制を全部発送した場合の実費
A30: S1：全員が発送を選択 | B30: =IF(OR(B5="",'設計入力'!D9=""),"",B5-B25-B27*'設計入力'!D9) | D30: 物販として最悪のケース。売上 −（発送実費）−（pt限定×原価率）
A31: S2：全員がpt変換（額面＝最悪ケース） | B31: =IF(B5="","",B5-B26-B27-B28) -> 22750 | D31: 付与ptを1pt=1円の負債とみなす会計上の最悪ケース
A32: S3：全員がpt変換（実質原価評価） | B32: =IF(OR(B5="",'設計入力'!D9=""),"",B5-B26-(B27+B28)*'設計入力'!D9) | D32: 付与ptを実質原価（既定0.72円/pt）で評価した現実的ケース
A33: 実測変換率（運用開始後に更新・初期値0.9） | B33: 0.9 | D33: 実際にpt変換を選んだ割合。運用データが出たらここを更新
A34: S4：実測変換率での損益 | B34: =IF(OR(B5="",B33="",'設計入力'!D9=""),"",B5-B26-(1-B33)*B29-B33*B28*'設計入力'!D9-B27*'設計入力'!D9) | D34: 実測に基づく着地見込み。S1〜S3の間に収まるのが普通
A35: 最大損失（S1〜S3のいちばん悪い値） | B35: =IF(OR(B30="",B31="",B32=""),"",MIN(B30:B32)) | D35: どのシナリオでも、ここまでしか損しないという下限
A36: 許容損失ライン（マイナスで入力） | B36: -3000000 | C36: =IF(OR(B35="",B36=""),"未入力",IF(B35>=B36,"OK 許容範囲内","NG 最大損失が許容ラインを超過（役員承認が必要）")) -> 未入力 | D36: 会社として耐えられる赤字の下限。超えるなら設計を縮小するか役員承認を取る
A38: 途中終了リスク（売れ止まり × 上位賞先出し・保守評価）
A39: 上位賞（pt限定以外）の口数 | B39: =SUMIF('設計入力'!G13:G33,"<>pt限定",'設計入力'!D13:D33) -> 50 | D39: 1等〜下位賞まで、保証以外の口数合計
A40: 上位賞の最悪費用（額面） | B40: =B26+MAX(B29,B28) -> 800800 | D40: 上位賞が全部出た場合のコスト。選択制は「実費」と「額面pt」の高い方で見る保守評価
A41: 回収に必要な売上進捗率 | B41: =IF(OR(B5="",B5=0),"",B40/B5) -> 0.94729993 | D41: これ以上売れた時点なら、上位賞が全部先に出ても赤字なし（保証分は僅少のため除いた概算）。100%超＝完売でも額面最悪は赤字（S2参照）
A42: 想定進捗率（売れ止まりの想定・入力） | B42: 0.3 | D42: 「ここまでしか売れなかったら」の想定。迷ったら30%。オリパは母集団固定なので途中終了時に上位賞が先に出ているのが最悪
A43: 想定進捗での最悪損益（上位賞先出し） | B43: =IF(OR(B5="",B42="",'設計入力'!D6=""),"",B42*B5-B40-MAX(0,B42*'設計入力'!D6-B39)*IF(SUMIF('設計入力'!G13:G33,"pt限定",'設計入力'!D13:D33)=0,0,B27/SUMIF('設計入力'!G13:G33,"pt限定",'設計入力'!D13:D33))) -> -553687.01 | C43: =IF(B43="","未入力",IF(B43>=0,"OK 想定進捗でも赤字なし",IF(OR(B36="",B43>=B36),"注意 想定進捗で最大 "&TEXT(B43,"#,##0")&" 円の赤字（許容内・要認識）","NG 途中終了時の損失が許容ラインを超過"))) -> 注意 想定進捗で最大 -553,687 円の赤字（許容内・要認識） | D43: 進捗にかかわらず上位賞は全放出とみなす保守評価（回収進捗率より下では常に過大側）。売り切る販促計画とセットで判断
...

Sheet 公開前チェック
A1: ③ 公開前チェック — バナー表記との突合＋手動確認
A2: バナー・LP・X告知に書いた数字をB列に入力すると実装値と自動突合。手動チェックリストも全部埋めると、いちばん下の■公開前総合がOKになる。
A3: 項目 | B3: バナー記載値（入力） | C3: 実装値（自動） | D3: 判定 | E3: 説明
A4: 総還元率 | C4: ='自動判定'!B8 -> 0.97308807 | D4: =IF(OR(B4="",C4=""),"未入力（バナー値を入力）",IF(C4>=B4-0.0049,"OK 表記以上","NG 実装が表記を下回る（優良誤認のおそれ）")) -> 未入力（バナー値を入力） | E4: 実装 ≧ 表記 ならOK（0.49ptの丸め許容）。下回ると景表法の優良誤認リスク
A5: 「Xpt以上が1/Y」の X（pt） | B5: 81900 | C5: =IF(B5="","",SUMIFS('設計入力'!D13:D33,'設計入力'!J13:J33,">="&B5)) -> 0 | E5: 実装値＝表示PTがXpt以上の賞の口数合計
A6: 同 Y（1/Yの分母） | B6: 319 | C6: =IF(OR(B5="",C5="",C5=0),"",'設計入力'!D6/C5) | D6: =IF(OR(B6="",C6=""),"未入力",IF(C6<=B6,"OK 表記より有利","NG 実確率が表記より不利（要修正）")) -> 未入力 | E6: 実装値＝総口数÷該当口数。バナーのYは実装値より大きい数字（不利側）に丸めて書く
A7: 2組目の X（pt）※任意 | C7: =IF(B7="","",SUMIFS('設計入力'!D13:D33,'設計入力'!J13:J33,">="&B7)) | E7: バナーに確率表記が2段ある場合のみ入力（例：10万pt以上と5万pt以上）
A8: 2組目の Y ※任意 | C8: =IF(OR(B7="",C7="",C7=0),"",'設計入力'!D6/C7) | D8: =IF(AND(B7="",B8=""),"—（未使用）",IF(OR(B7="",B8="",C8=""),"未入力（XとYを両方入力）",IF(C8<=B8,"OK 表記より有利","NG 実確率が表記より不利（要修正）"))) -> —（未使用） | E8: 使わないなら両方空欄でOK（グレー表示のまま）
A9: 最低保証（pt） | B9: 1 | C9: =IF('設計入力'!K34=0,"",MIN('設計入力'!J13:J33)) -> 0 | D9: =IF(OR(B9="",C9=""),"未入力",IF(C9>=B9,"OK","NG 最低保証を下回る賞が存在")) -> NG 最低保証を下回る賞が存在 | E9: 実装値＝表示PT/枚のいちばん小さい値。バナーの保証額以上ならOK
A11: 手動チェックリスト（全項目に担当・完了日が入るまで公開不可）
A12: 項目 | B12: 担当 | C12: 完了日
A13: 管理画面の実装値とこのシートのスクリーンショット突合
A14: 齊田先生レビュー（還元率表記・確率表記・規約）
A15: テスト抽選（10回以上・付与ptと表示の一致確認）
A16: 1人あたり購入上限の実装確認（現金・pt共通）
A17: 監視アラート設定（現金比率／上位10口座シェア／払出÷投入比／秒間抽選数）
A18: 仮名称・プレースホルダー賞品の除去確認
A19: 設計シート内の旧バージョン・旧メモの削除
A21: 手動チェックの完了状況 | B21: =SUMPRODUCT((B13:B19<>"")*(C13:C19<>""))&" / 7" -> 0 / 7 | D21: =IF(SUMPRODUCT((B13:B19<>"")*(C13:C19<>""))=7,"OK 全項目完了","未完了 "&(7-SUMPRODUCT((B13:B19<>"")*(C13:C19<>"")))&" 件") -> 未完了 7 件 | E21: 担当と完了日の両方が入った行を完了とカウント
A23: ■ 公開前総合 | D23: =IF('自動判定'!C49="","未入力（自動判定を先に完成）",IF(LEFT('自動判定'!C49,2)="NG","NG 自動判定がNGのため公開不可",IF(COUNTIF(D4:D21,"NG*")>0,"NG バナー表記の乖離を修正してください",IF(OR(COUNTIF(D4:D21,"未入*")>0,COUNTIF(D4:D21,"未完*")>0,LEFT('自動判定'!C49,2)="未入"),"未完了 — 未入力/未完了を解消してください","OK 公開準備完了")))) -> NG バナー表記の乖離を修正してください | E23: 自動判定OK＋バナー突合OK＋手動7項目完了 がそろって初めてOK

Sheet 計算式リスト
A1: ④ 計算式リスト — この表の全計算式＋自分で計算するときの式（数値例はすべてデモの数字）
A2: No. | B2: どこの数字？ | C2: 名前 | D2: 意味・ことばの式 | E2: Excelの式 | F2: 数値例（デモ）
A3: A. まず覚える3つの基本式（この3つだけで判定の意味がわかる）
A4: A-1 | B4: 自動判定 B6 | C4: 総売上 | D4: 単価 × 総口数。完売したときにお客様から入るptの総額（1pt＝1円） | E4: ＝設計入力!D6*設計入力!D7 | F4: 800 × 5,000口 ＝ 4,000,000pt
A5: A-2 | B5: 自動判定 B9 | C5: 総還元率 | D5: 表示PT合計 ÷ 総売上。バナーに書く「◯%」 | E5: ＝B8/B6 | F5: 4,330,000 ÷ 4,000,000 ＝ 108.25%
A6: A-3 | B6: 自動判定 B14 | C6: ★実効pt建てEV | D6: 単体EV（(表示PT合計−発送限定)÷総売上）に、クーポン・紹介pt等の外部付与見込みを足したもの。100%以上でptが増殖して再投入ループ成立（＝末広がり事案）。安全上限95%以上は注意 | E6: ＝(B8-B10)/B6 + 外部付与率 | F6: 103.25% ＋ 2% ＝ 105.25% → 100%以上なのでNG
A7: B. 設計入力シートの自動計算（J〜M列と合計行）
A8: B-1 | B8: 設計入力 J列 | C8: 表示PT/枚 | D8: その賞を引いたとき画面に出るpt。「表示PT直接指定」があればその値。空欄なら 実価値 × 上乗せ倍率（四捨五入） | E8: ＝IF(I="","実価値×倍率",I) | F8: 2等：50,000 × 1.2 ＝ 60,000pt ／ 最低保証：直接指定 65pt
A9: B-2 | B9: 設計入力 K列 | C9: 表示PT小計 | D9: 口数 × 表示PT/枚。その賞ランク全体で付与しうるpt | E9: ＝D×J | F9: 4等：950口 × 2,600 ＝ 2,470,000pt
A10: B-3 | B10: 設計入力 L列 | C10: 実価値小計 | D10: 口数 × 実価値/枚。カードの仕入れ相当額 | E10: ＝D×E | F10: 4等：950口 × 2,000 ＝ 1,900,000円
A11: B-4 | B11: 設計入力 M列 | C11: 出現率 | D11: 口数 ÷ 総口数。1口買ってその賞が当たる確率 | E11: ＝D/総口数 | F11: 4等：950 ÷ 5,000 ＝ 19.00%
A12: B-5 | B12: 設計入力 35行 | C12: 合計行 | D12: 各列のSUM。口数合計＝総口数、出現率合計＝100% になっていることが正常 | E12: ＝SUM(範囲) | F12: 口数 5,000（一致）／出現率 100.00%
A13: C. 自動判定シートの式（EV・完全性・損益）
A14: C-1 | B14: 自動判定 B10 | C14: 発送限定の表示PT | D14: 受取方法が「発送限定」の行だけK列を合計 | E14: ＝SUMIF(G列,"発送限定",K列) | F14: 1等のみ ＝ 200,000pt
A15: C-2 | B15: 自動判定 B12〜B15 | C15: 実効EVまわり | D15: 単体EV＝pt建て表示PT÷総売上。実効EV＝単体EV＋外部付与見込み（入力）。判定は 100%以上→NG／安全上限（入力・既定95%）以上→注意 | E15: ＝B12+B13、判定はIFの入れ子 | F15: 103.25%＋2%＝105.25% → NG
A16: C-3 | B16: 自動判定 B20〜B22 | C16: データ完全性 | D16: 口数が入っている行のうち、受取方法が空／表示PTが確定しない／実価値・送料が空（pt限定以外）の行数。1行でもあればNG（判定が甘くなる穴を塞ぐ） | E16: ＝SUMPRODUCT((D<>"")*(条件)) | F16: デモは全て0行 → OK
A17: C-4 | B17: 自動判定 B23 | C17: 在庫不足チェック | D17: 確保在庫（設計入力N列）を入れた行だけ、在庫＜口数ならNG。オーバーセル防止。N列が全部空なら未使用扱い | E17: ＝SUMPRODUCT((N<>"")*(N<D)) | F17: デモは4行チェックして不足0 → OK
A18: C-5 | B18: 自動判定 B26 | C18: 発送可能賞の実価値＋送料 | D18: pt限定以外（発送限定＋選択制）の実価値小計＋（口数×送料）の合計 | E18: ＝SUMIF(...)+SUMPRODUCT(...) | F18: 3,210,000 ＋ 908,000 ＝ 4,118,000円
A19: C-6 | B19: 自動判定 B31 | C19: S1：全員が発送 | D19: 売上 −（発送可能賞の実価値＋送料）−（pt限定の表示PT × 原価率0.72）。物販として最悪のケース | E19: ＝B6-B26-B28*原価率 | F19: 4,000,000 − 4,118,000 − 187,200 ＝ ▲305,200円
A20: C-7 | B20: 自動判定 B32 | C20: S2：全員pt変換（額面） | D20: 売上 − 発送限定の実費 − pt限定の表示PT − 選択制の表示PT。付与ptを1pt＝1円の負債と見る最悪ケース | E20: ＝B6-B27-B28-B29 | F20: 4,000,000 − 181,500 − 260,000 − 3,870,000 ＝ ▲311,500円
A21: C-8 | B21: 自動判定 B33 | C21: S3：全員pt変換（実質原価） | D21: 売上 − 発送限定の実費 −（pt限定＋選択制の表示PT）× 原価率0.72。現実的なケース | E21: ＝B6-B27-(B28+B29)*原価率 | F21: 4,000,000 − 181,500 − 2,973,600 ＝ ＋844,900円
A22: C-9 | B22: 自動判定 B35 | C22: S4：実測変換率での損益 | D22: 売上 − 発送限定実費 −（発送を選んだ分の実費）−（pt変換分×0.72）−（pt限定×0.72）。変換率rは運用データで更新 | E22: ＝B6-B27-(1-r)*B30-r*B29*原価率-B28*原価率 | F22: r＝0.9 で ＋729,890円
A23: C-10 | B23: 自動判定 B36 | C23: 最大損失 | D23: S1〜S3のいちばん小さい値。どのシナリオでもこれ以上は損しない下限 | E23: ＝MIN(S1:S3) | F23: ▲311,500円 → 許容ライン▲3,000,000円の範囲内でOK
A24: C-11 | B24: 自動判定 B47 | C24: 仮名称・デモ名カウント | D24: 賞品名に なにか/TBD/テスト/仮/デモ/サンプル/ダミー/test を含む行数（「仮面」は除外）。1件でもNG | E24: ＝ΣSUMPRODUCT(SEARCH(語))−SEARCH("仮面")分 | F24: デモは「デモ」5件 → 意図どおりNG
A25: D. 自動判定シートの式（途中終了リスク＝売れ止まり×上位賞先出し）
A26: D-1 | B26: 自動判定 B40・B41 | C26: 上位賞の口数と最悪費用 | D26: 上位賞＝pt限定以外の全部。最悪費用＝発送限定の実費＋MAX(選択制の実費, 選択制の額面pt)。「高い方」で見る保守評価 | E26: ＝B27+MAX(B30,B29) | F26: 181,500 ＋ MAX(3,936,500, 3,870,000) ＝ 4,118,000円
A27: D-2 | B27: 自動判定 B42 | C27: 回収に必要な売上進捗率 | D27: 上位賞の最悪費用 ÷ 総売上。これ以上売れていれば、上位賞が全部先に出ても赤字なし。100%超＝完売でも額面最悪は赤字（S2と同じ話） | E27: ＝B41/B6 | F27: 4,118,000 ÷ 4,000,000 ＝ 103.0% → デモは完売でも額面最悪は赤字
A28: D-3 | B28: 自動判定 B44 | C28: 想定進捗での最悪損益 | D28: 想定進捗p（入力・既定30%）で売れ止まり、かつ上位賞が全部出ていた場合。＝p×総売上 − 上位賞最悪費用 − 保証の消化分（p×総口数が上位口数を超えた分×平均保証pt）。赤字が許容ライン内なら注意、超えたらNG | E28: ＝p*B6-B41-MAX(0,p*総口数-B40)*平均保証pt | F28: 30%×4,000,000 − 4,118,000 − 500口×65 ＝ ▲2,950,500円 → 許容内なので注意
A29: E. 公開前チェックシートの式
A30: E-1 | B30: 公開前 C5 | C30: 実装の総還元率 | D30: 自動判定の総還元率をそのまま参照。バナー値との差が−0.49pt以内ならOK | E30: ＝'自動判定'!B9 | F30: 108.25% ≧ バナー108% → OK
A31: E-2 | B31: 公開前 C6/C8 | C31: Xpt以上の該当口数 | D31: 表示PT/枚がXpt以上の賞の口数合計。2段表記のバナー用に2組目（任意）もある | E31: ＝SUMIFS(D列,J列,">="&X) | F31: X＝60,000pt → 1等1口＋2等5口 ＝ 6口
A32: E-3 | B32: 公開前 C7/C9 | C32: 実際の1/Yの分母 | D32: 総口数 ÷ 該当口数。バナーには実装値より大きい（＝お客様に不利な）数字を書く | E32: ＝総口数/該当口数 | F32: 5,000 ÷ 6 ＝ 833.3 → バナーは「1/834」ならOK
A33: E-4 | B33: 公開前 C10 | C33: 実装の最低保証 | D33: 表示PT/枚（J列）のいちばん小さい値 | E33: ＝MIN(J列) | F33: 65pt ≧ バナー65pt → OK
A34: E-5 | B34: 公開前 D22・D24 | C34: 手動完了と公開前総合 | D34: 手動チェックは担当＋完了日の両方が入った行を完了とカウント（7/7で完了）。公開前総合＝自動判定OK＋バナー突合OK＋手動7項目完了 の全部そろいでOK | E34: ＝SUMPRODUCT((担当<>"")*(完了日<>"")) | F34: デモは手動未記入 → 未完了 7件
A35: F. 損害計算シート（末広がり事案）の式
A36: F-1 | B36: 損害計算 B14 | C36: Δpt残高（額面） | D36: このガチャが付与したpt − このガチャに投入されたpt。プラス＝ptが市中に増えた分 | E36: ＝付与pt-投入pt | F36: コーナーズのクエリ回答で確定
A37: F-2 | B37: 損害計算 B15 | C37: Δptの実質コスト | D37: Δpt残高 × 実質原価率0.72。増えたptを商品で消化するときの実費 | E37: ＝Δpt×0.72 | F37: 同上
A38: F-3 | B38: 損害計算 B16/B17 | C38: 4等の発送実費／未選択引当 | D38: 当選件数 × 発送選択率 × 実費/件 ／ 当選件数 × 未選択率 × 引当/件 | E38: ＝件数×率×単価 | F38: 同上
A39: F-4 | B39: 損害計算 B18 | C39: 損害合計（推計） | D39: 現金収入 − 1等実費 − 4等発送実費 − 4等引当 − Δpt実質コスト。マイナス＝損害額 | E39: ＝B4-B5-B16-B17-B15 | F39: 再投入pt分はΔptに織り込み済み（二重計上しない）
A40: G. ★自分で設計するときに電卓で使う逆算式（新しいガチャを作る手順そのまま）
...

Sheet 損害計算(末広がり事案)
A1: ⑤ 末広がり事案の損害計算 — コーナーズのクエリ回答で黄色セルを埋めると確定値が出ます
A2: 項目 | B2: 値 | C2: 説明
A3: 現金収入（円） | C3: 本ガチャの現金決済売上（コーナーズ回答）
A4: 1等 発送原価＋送料保険（円） | C4: 1等の実費
A5: 本ガチャへの投入pt総額 | C5: お客様が本ガチャに使ったpt（要クエリ）
A6: 本ガチャの変換付与pt総額 | C6: 本ガチャが付与したpt（要クエリ）
A7: 4等 当選件数 | C7: 件数
A8: 4等 発送選択率 | C8: 0〜1で入力（例：0.35）
A9: 4等 未選択率 | C9: 0〜1で入力。発送選択率＋未選択率＝1
A10: 4等 発送実費/件（円） | C10: 1件あたりの発送コスト
A11: 4等 未選択引当/件（円） | C11: 未選択分の引当単価
A12: pt実質原価率（設計入力より） | B12: ='設計入力'!D9 | C12: 設計入力の値を自動参照
A13: Δpt残高（額面）＝付与−投入 | B13: =IF(OR(B5="",B6=""),"",B6-B5) | C13: プラス＝ptが増えた分
A14: Δpt残高の実質コスト | B14: =IF(OR(B13="",B12=""),"",B13*B12) | C14: Δpt × 原価率
A15: 4等 発送実費 | B15: =IF(OR(B7="",B8="",B10=""),"",B7*B8*B10) | C15: 件数×発送選択率×実費/件
A16: 4等 未選択引当 | B16: =IF(OR(B7="",B9="",B11=""),"",B7*B9*B11) | C16: 件数×未選択率×引当/件
A17: ■ 損害合計（現時点推計） | B17: =IF(OR(B3="",B4="",B14="",B15="",B16=""),"",B3-B4-B15-B16-B14) | C17: マイナス＝損害額。プラスなら持ち出しなし
A19: ※ 変換済みで再投入されたptのコストはΔpt残高に織り込み済み（二重計上しないこと）。
A20: ※ プラットフォーム全体のpt負債は別途：SUM(全ウォレット残高) × 実質原価率 を税理士と会計計上。
